<?xml version="1.0" ?>
<!-- ABB YuMi IRB 14000 Right Arm URDF - 7-DOF, no meshes -->
<!-- Joint axes: Z, Y, Z, Y, Z, Y, Z -->
<!-- DH from ABB: d=[0.1663, 0, 0.2515, 0, 0.2653, 0, 0.036], a=[0.030, 0, 0, 0, 0, 0, 0] -->
<!-- Right arm configuration (mirrored from left) -->
<robot name="abb_yumi_right">
  <link name="base_link">
    <inertial>
      <mass value="5.0"/>
      <inertia ixx="0.03" ixy="0.0" ixz="0.0" iyy="0.03" iyz="0.0" izz="0.03"/>
    </inertial>
  </link>

  <joint name="yumi_joint_1_r" type="revolute">
    <parent link="base_link"/>
    <child link="link_1_r"/>
    <origin xyz="0.030 -0.1386 0.1663" rpy="0 0 0"/>
    <axis xyz="0 0 1"/>
    <limit lower="-2.9409" upper="2.9409" effort="12.0" velocity="3.054"/>
  </joint>

  <link name="link_1_r">
    <inertial>
      <mass value="2.0"/>
      <inertia ixx="0.005" ixy="0.0" ixz="0.0" iyy="0.005" iyz="0.0" izz="0.003"/>
    </inertial>
  </link>

  <joint name="yumi_joint_2_r" type="revolute">
    <parent link="link_1_r"/>
    <child link="link_2_r"/>
    <origin xyz="0 0 0" rpy="0 0 0"/>
    <axis xyz="0 1 0"/>
    <limit lower="-2.5045" upper="0.7592" effort="12.0" velocity="3.054"/>
  </joint>

  <link name="link_2_r">
    <inertial>
      <mass value="2.0"/>
      <inertia ixx="0.005" ixy="0.0" ixz="0.0" iyy="0.005" iyz="0.0" izz="0.003"/>
    </inertial>
  </link>

  <joint name="yumi_joint_3_r" type="revolute">
    <parent link="link_2_r"/>
    <child link="link_3_r"/>
    <origin xyz="0 0 0.2515" rpy="0 0 0"/>
    <axis xyz="0 0 1"/>
    <limit lower="-2.9409" upper="2.9409" effort="7.0" velocity="3.054"/>
  </joint>

  <link name="link_3_r">
    <inertial>
      <mass value="1.0"/>
      <inertia ixx="0.002" ixy="0.0" ixz="0.0" iyy="0.002" iyz="0.0" izz="0.001"/>
    </inertial>
  </link>

  <joint name="yumi_joint_4_r" type="revolute">
    <parent link="link_3_r"/>
    <child link="link_4_r"/>
    <origin xyz="0 0 0" rpy="0 0 0"/>
    <axis xyz="0 1 0"/>
    <limit lower="-2.1642" upper="1.3963" effort="7.0" velocity="5.027"/>
  </joint>

  <link name="link_4_r">
    <inertial>
      <mass value="0.8"/>
      <inertia ixx="0.001" ixy="0.0" ixz="0.0" iyy="0.001" iyz="0.0" izz="0.0005"/>
    </inertial>
  </link>

  <joint name="yumi_joint_5_r" type="revolute">
    <parent link="link_4_r"/>
    <child link="link_5_r"/>
    <origin xyz="0 0 0.2653" rpy="0 0 0"/>
    <axis xyz="0 0 1"/>
    <limit lower="-5.0615" upper="5.0615" effort="5.0" velocity="5.027"/>
  </joint>

  <link name="link_5_r">
    <inertial>
      <mass value="0.5"/>
      <inertia ixx="0.0005" ixy="0.0" ixz="0.0" iyy="0.0005" iyz="0.0" izz="0.0003"/>
    </inertial>
  </link>

  <joint name="yumi_joint_6_r" type="revolute">
    <parent link="link_5_r"/>
    <child link="link_6_r"/>
    <origin xyz="0 0 0" rpy="0 0 0"/>
    <axis xyz="0 1 0"/>
    <limit lower="-1.5359" upper="2.4087" effort="5.0" velocity="5.027"/>
  </joint>

  <link name="link_6_r">
    <inertial>
      <mass value="0.3"/>
      <inertia ixx="0.0003" ixy="0.0" ixz="0.0" iyy="0.0003" iyz="0.0" izz="0.0002"/>
    </inertial>
  </link>

  <joint name="yumi_joint_7_r" type="revolute">
    <parent link="link_6_r"/>
    <child link="link_7_r"/>
    <origin xyz="0 0 0.036" rpy="0 0 0"/>
    <axis xyz="0 0 1"/>
    <limit lower="-3.9968" upper="3.9968" effort="5.0" velocity="5.027"/>
  </joint>

  <link name="link_7_r">
    <inertial>
      <mass value="0.2"/>
      <inertia ixx="0.0001" ixy="0.0" ixz="0.0" iyy="0.0001" iyz="0.0" izz="0.0001"/>
    </inertial>
  </link>

  <joint name="ee_fixed_joint" type="fixed">
    <parent link="link_7_r"/>
    <child link="tool0"/>
    <origin xyz="0 0 0" rpy="0 0 0"/>
  </joint>

  <link name="tool0">
    <inertial>
      <mass value="0.0"/>
      <inertia ixx="0.0" ixy="0.0" ixz="0.0" iyy="0.0" iyz="0.0" izz="0.0"/>
    </inertial>
  </link>
</robot>
