<?xml version="1.0"?>
<!-- Simplified KUKA iiwa 14 URDF - correct kinematics, no meshes -->
<!-- 7-DOF redundant manipulator, all joints rotate about Z axis -->
<!-- Alternating rpy rotations convert Z-axis rotation to effective Y-axis motion -->
<robot name="kuka_iiwa14">
  <link name="iiwa_link_0">
    <inertial>
      <mass value="5.0"/>
      <inertia ixx="0.05" ixy="0.0" ixz="0.0" iyy="0.05" iyz="0.0" izz="0.03"/>
    </inertial>
    <collision>
      <origin xyz="0 0 0.05" rpy="0 0 0"/>
      <geometry>
        <cylinder radius="0.08" length="0.10"/>
      </geometry>
    </collision>
  </link>

  <joint name="iiwa_joint_1" type="revolute">
    <parent link="iiwa_link_0"/>
    <child link="iiwa_link_1"/>
    <origin xyz="0 0 0.1575" rpy="0 0 0"/>
    <axis xyz="0 0 1"/>
    <limit lower="-2.9671" upper="2.9671" effort="320" velocity="1.57"/>
  </joint>

  <link name="iiwa_link_1">
    <inertial>
      <mass value="4.0"/>
      <inertia ixx="0.03" ixy="0.0" ixz="0.0" iyy="0.03" iyz="0.0" izz="0.012"/>
    </inertial>
    <collision>
      <origin xyz="0 0 0.1013" rpy="0 0 0"/>
      <geometry>
        <cylinder radius="0.07" length="0.19"/>
      </geometry>
    </collision>
  </link>

  <joint name="iiwa_joint_2" type="revolute">
    <parent link="iiwa_link_1"/>
    <child link="iiwa_link_2"/>
    <origin xyz="0 0 0.2025" rpy="1.5708 0 0"/>
    <axis xyz="0 0 1"/>
    <limit lower="-2.0944" upper="2.0944" effort="320" velocity="1.57"/>
  </joint>

  <link name="iiwa_link_2">
    <inertial>
      <mass value="4.0"/>
      <inertia ixx="0.03" ixy="0.0" ixz="0.0" iyy="0.03" iyz="0.0" izz="0.012"/>
    </inertial>
    <collision>
      <origin xyz="0 0.1023 0" rpy="1.5708 0 0"/>
      <geometry>
        <cylinder radius="0.065" length="0.19"/>
      </geometry>
    </collision>
  </link>

  <joint name="iiwa_joint_3" type="revolute">
    <parent link="iiwa_link_2"/>
    <child link="iiwa_link_3"/>
    <origin xyz="0 0.2045 0" rpy="-1.5708 0 0"/>
    <axis xyz="0 0 1"/>
    <limit lower="-2.9671" upper="2.9671" effort="320" velocity="1.57"/>
  </joint>

  <link name="iiwa_link_3">
    <inertial>
      <mass value="3.0"/>
      <inertia ixx="0.02" ixy="0.0" ixz="0.0" iyy="0.02" iyz="0.0" izz="0.01"/>
    </inertial>
    <collision>
      <origin xyz="0 0 0.1078" rpy="0 0 0"/>
      <geometry>
        <cylinder radius="0.06" length="0.20"/>
      </geometry>
    </collision>
  </link>

  <joint name="iiwa_joint_4" type="revolute">
    <parent link="iiwa_link_3"/>
    <child link="iiwa_link_4"/>
    <origin xyz="0 0 0.2155" rpy="1.5708 0 0"/>
    <axis xyz="0 0 1"/>
    <limit lower="-2.0944" upper="2.0944" effort="320" velocity="1.57"/>
  </joint>

  <link name="iiwa_link_4">
    <inertial>
      <mass value="2.7"/>
      <inertia ixx="0.015" ixy="0.0" ixz="0.0" iyy="0.015" iyz="0.0" izz="0.007"/>
    </inertial>
    <collision>
      <origin xyz="0 0.0923 0" rpy="1.5708 0 0"/>
      <geometry>
        <cylinder radius="0.055" length="0.17"/>
      </geometry>
    </collision>
  </link>

  <joint name="iiwa_joint_5" type="revolute">
    <parent link="iiwa_link_4"/>
    <child link="iiwa_link_5"/>
    <origin xyz="0 0.1845 0" rpy="-1.5708 0 0"/>
    <axis xyz="0 0 1"/>
    <limit lower="-2.9671" upper="2.9671" effort="176" velocity="1.57"/>
  </joint>

  <link name="iiwa_link_5">
    <inertial>
      <mass value="1.7"/>
      <inertia ixx="0.01" ixy="0.0" ixz="0.0" iyy="0.01" iyz="0.0" izz="0.005"/>
    </inertial>
    <collision>
      <origin xyz="0 0 0.1078" rpy="0 0 0"/>
      <geometry>
        <cylinder radius="0.05" length="0.20"/>
      </geometry>
    </collision>
  </link>

  <joint name="iiwa_joint_6" type="revolute">
    <parent link="iiwa_link_5"/>
    <child link="iiwa_link_6"/>
    <origin xyz="0 0 0.2155" rpy="1.5708 0 0"/>
    <axis xyz="0 0 1"/>
    <limit lower="-2.0944" upper="2.0944" effort="176" velocity="1.57"/>
  </joint>

  <link name="iiwa_link_6">
    <inertial>
      <mass value="1.8"/>
      <inertia ixx="0.005" ixy="0.0" ixz="0.0" iyy="0.005" iyz="0.0" izz="0.003"/>
    </inertial>
    <collision>
      <origin xyz="0 0.0405 0" rpy="1.5708 0 0"/>
      <geometry>
        <cylinder radius="0.045" length="0.07"/>
      </geometry>
    </collision>
  </link>

  <joint name="iiwa_joint_7" type="revolute">
    <parent link="iiwa_link_6"/>
    <child link="iiwa_link_7"/>
    <origin xyz="0 0.081 0" rpy="-1.5708 0 0"/>
    <axis xyz="0 0 1"/>
    <limit lower="-2.9671" upper="2.9671" effort="176" velocity="1.57"/>
  </joint>

  <link name="iiwa_link_7">
    <inertial>
      <mass value="0.3"/>
      <inertia ixx="0.001" ixy="0.0" ixz="0.0" iyy="0.001" iyz="0.0" izz="0.0005"/>
    </inertial>
    <collision>
      <origin xyz="0 0 0.02" rpy="0 0 0"/>
      <geometry>
        <cylinder radius="0.04" length="0.04"/>
      </geometry>
    </collision>
  </link>

  <joint name="iiwa_joint_ee" type="fixed">
    <parent link="iiwa_link_7"/>
    <child link="iiwa_link_ee"/>
    <origin xyz="0 0 0.045" rpy="0 0 0"/>
  </joint>

  <link name="iiwa_link_ee">
    <inertial>
      <mass value="0.1"/>
      <inertia ixx="0.0001" ixy="0.0" ixz="0.0" iyy="0.0001" iyz="0.0" izz="0.00005"/>
    </inertial>
  </link>
</robot>
