<?xml version="1.0" ?>
<!-- UR10e URDF - correct kinematics matching ur_description, no meshes -->
<!-- Joint axes: Z, Y, Y, Y, Z, Y (standard UR convention) -->
<!-- DH: d=[0.1807, 0, 0, 0.1149, 0.1157, 0.0922], a=[0, -0.6127, -0.5716, 0, 0, 0] -->
<robot name="ur10e">
  <link name="base_link">
    <inertial>
      <mass value="5.0"/>
      <inertia ixx="0.01" ixy="0.0" ixz="0.0" iyy="0.01" iyz="0.0" izz="0.01"/>
    </inertial>
    <collision>
      <geometry><cylinder radius="0.090" length="0.1807"/></geometry>
      <origin xyz="0 0 0.090" rpy="0 0 0"/>
    </collision>
  </link>

  <joint name="shoulder_pan_joint" type="revolute">
    <parent link="base_link"/>
    <child link="shoulder_link"/>
    <origin xyz="0 0 0.1807" rpy="0 0 0"/>
    <axis xyz="0 0 1"/>
    <limit lower="-6.2832" upper="6.2832" effort="330.0" velocity="2.0944"/>
  </joint>

  <link name="shoulder_link">
    <inertial>
      <mass value="4.25"/>
      <inertia ixx="0.01" ixy="0.0" ixz="0.0" iyy="0.01" iyz="0.0" izz="0.01"/>
    </inertial>
    <collision>
      <geometry><cylinder radius="0.072" length="0.144"/></geometry>
      <origin xyz="0 0 0" rpy="0 0 0"/>
    </collision>
  </link>

  <joint name="shoulder_lift_joint" type="revolute">
    <parent link="shoulder_link"/>
    <child link="upper_arm_link"/>
    <origin xyz="0 0 0" rpy="0 0 0"/>
    <axis xyz="0 1 0"/>
    <limit lower="-6.2832" upper="6.2832" effort="330.0" velocity="2.0944"/>
  </joint>

  <link name="upper_arm_link">
    <inertial>
      <mass value="15.93"/>
      <inertia ixx="0.04" ixy="0.0" ixz="0.0" iyy="0.04" iyz="0.0" izz="0.02"/>
    </inertial>
    <collision>
      <geometry><cylinder radius="0.065" length="0.6127"/></geometry>
      <origin xyz="-0.3064 0 0" rpy="0 1.5708 0"/>
    </collision>
  </link>

  <joint name="elbow_joint" type="revolute">
    <parent link="upper_arm_link"/>
    <child link="forearm_link"/>
    <origin xyz="-0.6127 0 0" rpy="0 0 0"/>
    <axis xyz="0 1 0"/>
    <limit lower="-6.2832" upper="6.2832" effort="150.0" velocity="3.1416"/>
  </joint>

  <link name="forearm_link">
    <inertial>
      <mass value="4.231"/>
      <inertia ixx="0.02" ixy="0.0" ixz="0.0" iyy="0.02" iyz="0.0" izz="0.01"/>
    </inertial>
    <collision>
      <geometry><cylinder radius="0.055" length="0.5716"/></geometry>
      <origin xyz="-0.2858 0 0" rpy="0 1.5708 0"/>
    </collision>
  </link>

  <joint name="wrist_1_joint" type="revolute">
    <parent link="forearm_link"/>
    <child link="wrist_1_link"/>
    <origin xyz="-0.5716 0 0.1149" rpy="0 0 0"/>
    <axis xyz="0 1 0"/>
    <limit lower="-6.2832" upper="6.2832" effort="56.0" velocity="3.1416"/>
  </joint>

  <link name="wrist_1_link">
    <inertial>
      <mass value="1.219"/>
      <inertia ixx="0.001" ixy="0.0" ixz="0.0" iyy="0.001" iyz="0.0" izz="0.001"/>
    </inertial>
    <collision>
      <geometry><cylinder radius="0.046" length="0.108"/></geometry>
      <origin xyz="0 0 0" rpy="0 0 0"/>
    </collision>
  </link>

  <joint name="wrist_2_joint" type="revolute">
    <parent link="wrist_1_link"/>
    <child link="wrist_2_link"/>
    <origin xyz="0 -0.1157 0" rpy="0 0 0"/>
    <axis xyz="0 0 1"/>
    <limit lower="-6.2832" upper="6.2832" effort="56.0" velocity="3.1416"/>
  </joint>

  <link name="wrist_2_link">
    <inertial>
      <mass value="1.219"/>
      <inertia ixx="0.001" ixy="0.0" ixz="0.0" iyy="0.001" iyz="0.0" izz="0.001"/>
    </inertial>
    <collision>
      <geometry><cylinder radius="0.046" length="0.108"/></geometry>
      <origin xyz="0 0 0" rpy="0 0 0"/>
    </collision>
  </link>

  <joint name="wrist_3_joint" type="revolute">
    <parent link="wrist_2_link"/>
    <child link="wrist_3_link"/>
    <origin xyz="0 0.0922 0" rpy="0 0 0"/>
    <axis xyz="0 1 0"/>
    <limit lower="-6.2832" upper="6.2832" effort="56.0" velocity="3.1416"/>
  </joint>

  <link name="wrist_3_link">
    <inertial>
      <mass value="0.1889"/>
      <inertia ixx="0.0001" ixy="0.0" ixz="0.0" iyy="0.0001" iyz="0.0" izz="0.0001"/>
    </inertial>
    <collision>
      <geometry><cylinder radius="0.042" length="0.060"/></geometry>
      <origin xyz="0 0 0" rpy="0 0 0"/>
    </collision>
  </link>

  <joint name="ee_fixed_joint" type="fixed">
    <parent link="wrist_3_link"/>
    <child link="tool0"/>
    <origin xyz="0 0 0" rpy="0 0 0"/>
  </joint>

  <link name="tool0">
    <inertial>
      <mass value="0.0"/>
      <inertia ixx="0.0" ixy="0.0" ixz="0.0" iyy="0.0" iyz="0.0" izz="0.0"/>
    </inertial>
  </link>
</robot>
